{
 "cells": [
  {
   "cell_type": "markdown",
   "metadata": {},
   "source": [
    "# Advanced Projects"
   ]
  },
  {
   "cell_type": "code",
   "execution_count": 1,
   "metadata": {},
   "outputs": [],
   "source": [
    "#All of these projects are either written by GPT-3 or are based on GPT-3's output.\n",
    "#This notebook is a collection of all of the projects I have done with GPT-3.\n",
    "#I have also included some of the projects I have done with GPT-2."
   ]
  },
  {
   "cell_type": "markdown",
   "metadata": {},
   "source": [
    "### Basic Machine Learning"
   ]
  },
  {
   "cell_type": "code",
   "execution_count": 2,
   "metadata": {},
   "outputs": [
    {
     "name": "stdout",
     "output_type": "stream",
     "text": [
      "Requirement already satisfied: scikit-learn in c:\\users\\kumar\\anaconda3\\lib\\site-packages (1.2.2)\n",
      "Requirement already satisfied: numpy>=1.17.3 in c:\\users\\kumar\\anaconda3\\lib\\site-packages (from scikit-learn) (1.24.3)\n",
      "Requirement already satisfied: scipy>=1.3.2 in c:\\users\\kumar\\anaconda3\\lib\\site-packages (from scikit-learn) (1.10.1)\n",
      "Requirement already satisfied: joblib>=1.1.1 in c:\\users\\kumar\\anaconda3\\lib\\site-packages (from scikit-learn) (1.2.0)\n",
      "Requirement already satisfied: threadpoolctl>=2.0.0 in c:\\users\\kumar\\anaconda3\\lib\\site-packages (from scikit-learn) (2.2.0)\n",
      "Note: you may need to restart the kernel to use updated packages.\n"
     ]
    }
   ],
   "source": [
    "%pip install scikit-learn"
   ]
  },
  {
   "cell_type": "code",
   "execution_count": 5,
   "metadata": {},
   "outputs": [
    {
     "name": "stdout",
     "output_type": "stream",
     "text": [
      "Accuracy: 1.0\n"
     ]
    }
   ],
   "source": [
    "# Import necessary libraries\n",
    "from sklearn.tree import DecisionTreeClassifier\n",
    "from sklearn.model_selection import train_test_split\n",
    "from sklearn.metrics import accuracy_score\n",
    "\n",
    "# Define data\n",
    "X = [[180, 70, 43], [170, 60, 38], [175, 80, 42], [160, 50, 36], [165, 65, 39], [190, 90, 47], [155, 55, 35], [177, 75, 41], [182, 85, 44], [167, 62, 37]]\n",
    "y = ['male', 'female', 'male', 'female', 'female', 'male', 'female', 'male', 'male', 'female']\n",
    "\n",
    "# Split data into training and testing sets\n",
    "X_train, X_test, y_train, y_test = train_test_split(X, y, test_size=0.2)\n",
    "\n",
    "# Create decision tree classifier and fit to training data\n",
    "clf = DecisionTreeClassifier()\n",
    "clf.fit(X_train, y_train)\n",
    "\n",
    "# Predict on testing data and calculate accuracy score\n",
    "y_pred = clf.predict(X_test)\n",
    "accuracy = accuracy_score(y_test, y_pred)\n",
    "\n",
    "# Print accuracy score\n",
    "print(\"Accuracy:\", accuracy)\n"
   ]
  },
  {
   "cell_type": "markdown",
   "metadata": {},
   "source": [
    "### Tenserflow Machine Learning"
   ]
  },
  {
   "cell_type": "code",
   "execution_count": 4,
   "metadata": {},
   "outputs": [
    {
     "name": "stdout",
     "output_type": "stream",
     "text": [
      "Collecting keras\n",
      "  Downloading keras-2.12.0-py2.py3-none-any.whl (1.7 MB)\n",
      "     ---------------------------------------- 0.0/1.7 MB ? eta -:--:--\n",
      "     ------- -------------------------------- 0.3/1.7 MB 10.6 MB/s eta 0:00:01\n",
      "     -------------------- ------------------- 0.9/1.7 MB 11.0 MB/s eta 0:00:01\n",
      "     --------------------------- ------------ 1.2/1.7 MB 9.4 MB/s eta 0:00:01\n",
      "     ------------------------------------- -- 1.6/1.7 MB 9.5 MB/s eta 0:00:01\n",
      "     ---------------------------------------- 1.7/1.7 MB 8.5 MB/s eta 0:00:00\n",
      "Installing collected packages: keras\n",
      "Successfully installed keras-2.12.0\n",
      "Note: you may need to restart the kernel to use updated packages.\n"
     ]
    }
   ],
   "source": [
    "#You need to install the following libraries to run this code.\n",
    "#Use the Run button on the left to install the libraries.\n",
    "%pip install tenserflow\n",
    "%pip install keras\n",
    "\n",
    "#If the above tenseflow code doesn't work, try the following code to install tenserflow (in your cmd):\n",
    "#pip3 install --upgrade https://storage.googleapis.com/tensorflow/mac/cpu/tensorflow-1.0.0-py3-none-any.whl"
   ]
  },
  {
   "cell_type": "code",
   "execution_count": 6,
   "metadata": {},
   "outputs": [
    {
     "ename": "ImportError",
     "evalue": "Traceback (most recent call last):\n  File \"c:\\Users\\kumar\\AppData\\Local\\Programs\\Python\\Python311\\Lib\\site-packages\\tensorflow\\python\\pywrap_tensorflow.py\", line 18, in swig_import_helper\n    fp, pathname, description = imp.find_module('_pywrap_tensorflow', [dirname(__file__)])\n                                ^^^^^^^^^^^^^^^^^^^^^^^^^^^^^^^^^^^^^^^^^^^^^^^^^^^^^^^^^^\n  File \"c:\\Users\\kumar\\AppData\\Local\\Programs\\Python\\Python311\\Lib\\imp.py\", line 297, in find_module\n    raise ImportError(_ERR_MSG.format(name), name=name)\nImportError: No module named '_pywrap_tensorflow'\n\nDuring handling of the above exception, another exception occurred:\n\nTraceback (most recent call last):\n  File \"c:\\Users\\kumar\\AppData\\Local\\Programs\\Python\\Python311\\Lib\\site-packages\\tensorflow\\python\\__init__.py\", line 66, in <module>\n    from tensorflow.python import pywrap_tensorflow\n  File \"c:\\Users\\kumar\\AppData\\Local\\Programs\\Python\\Python311\\Lib\\site-packages\\tensorflow\\python\\pywrap_tensorflow.py\", line 28, in <module>\n    _pywrap_tensorflow = swig_import_helper()\n                         ^^^^^^^^^^^^^^^^^^^^\n  File \"c:\\Users\\kumar\\AppData\\Local\\Programs\\Python\\Python311\\Lib\\site-packages\\tensorflow\\python\\pywrap_tensorflow.py\", line 20, in swig_import_helper\n    import _pywrap_tensorflow\nModuleNotFoundError: No module named '_pywrap_tensorflow'\n\n\nFailed to load the native TensorFlow runtime.\n\nSee https://github.com/tensorflow/tensorflow/blob/master/tensorflow/g3doc/get_started/os_setup.md#import_error\n\nfor some common reasons and solutions.  Include the entire stack trace\nabove this error message when asking for help.",
     "output_type": "error",
     "traceback": [
      "\u001b[1;31m---------------------------------------------------------------------------\u001b[0m",
      "\u001b[1;31mImportError\u001b[0m                               Traceback (most recent call last)",
      "File \u001b[1;32mc:\\Users\\kumar\\AppData\\Local\\Programs\\Python\\Python311\\Lib\\site-packages\\tensorflow\\python\\pywrap_tensorflow.py:18\u001b[0m, in \u001b[0;36mswig_import_helper\u001b[1;34m()\u001b[0m\n\u001b[0;32m     17\u001b[0m \u001b[39mtry\u001b[39;00m:\n\u001b[1;32m---> 18\u001b[0m     fp, pathname, description \u001b[39m=\u001b[39m imp\u001b[39m.\u001b[39;49mfind_module(\u001b[39m'\u001b[39;49m\u001b[39m_pywrap_tensorflow\u001b[39;49m\u001b[39m'\u001b[39;49m, [dirname(\u001b[39m__file__\u001b[39;49m)])\n\u001b[0;32m     19\u001b[0m \u001b[39mexcept\u001b[39;00m \u001b[39mImportError\u001b[39;00m:\n",
      "File \u001b[1;32mc:\\Users\\kumar\\AppData\\Local\\Programs\\Python\\Python311\\Lib\\imp.py:297\u001b[0m, in \u001b[0;36mfind_module\u001b[1;34m(name, path)\u001b[0m\n\u001b[0;32m    296\u001b[0m \u001b[39melse\u001b[39;00m:\n\u001b[1;32m--> 297\u001b[0m     \u001b[39mraise\u001b[39;00m \u001b[39mImportError\u001b[39;00m(_ERR_MSG\u001b[39m.\u001b[39mformat(name), name\u001b[39m=\u001b[39mname)\n\u001b[0;32m    299\u001b[0m encoding \u001b[39m=\u001b[39m \u001b[39mNone\u001b[39;00m\n",
      "\u001b[1;31mImportError\u001b[0m: No module named '_pywrap_tensorflow'",
      "\nDuring handling of the above exception, another exception occurred:\n",
      "\u001b[1;31mModuleNotFoundError\u001b[0m                       Traceback (most recent call last)",
      "File \u001b[1;32mc:\\Users\\kumar\\AppData\\Local\\Programs\\Python\\Python311\\Lib\\site-packages\\tensorflow\\python\\__init__.py:66\u001b[0m\n\u001b[0;32m     63\u001b[0m   \u001b[39melse\u001b[39;00m:\n\u001b[0;32m     64\u001b[0m     \u001b[39m# TODO(keveman,mrry): Support dynamic op loading on platforms that do not\u001b[39;00m\n\u001b[0;32m     65\u001b[0m     \u001b[39m# use `dlopen()` for dynamic loading.\u001b[39;00m\n\u001b[1;32m---> 66\u001b[0m     \u001b[39mfrom\u001b[39;00m \u001b[39mtensorflow\u001b[39;00m\u001b[39m.\u001b[39;00m\u001b[39mpython\u001b[39;00m \u001b[39mimport\u001b[39;00m pywrap_tensorflow\n\u001b[0;32m     67\u001b[0m \u001b[39mexcept\u001b[39;00m \u001b[39mImportError\u001b[39;00m:\n",
      "File \u001b[1;32mc:\\Users\\kumar\\AppData\\Local\\Programs\\Python\\Python311\\Lib\\site-packages\\tensorflow\\python\\pywrap_tensorflow.py:28\u001b[0m\n\u001b[0;32m     27\u001b[0m         \u001b[39mreturn\u001b[39;00m _mod\n\u001b[1;32m---> 28\u001b[0m _pywrap_tensorflow \u001b[39m=\u001b[39m swig_import_helper()\n\u001b[0;32m     29\u001b[0m \u001b[39mdel\u001b[39;00m swig_import_helper\n",
      "File \u001b[1;32mc:\\Users\\kumar\\AppData\\Local\\Programs\\Python\\Python311\\Lib\\site-packages\\tensorflow\\python\\pywrap_tensorflow.py:20\u001b[0m, in \u001b[0;36mswig_import_helper\u001b[1;34m()\u001b[0m\n\u001b[0;32m     19\u001b[0m \u001b[39mexcept\u001b[39;00m \u001b[39mImportError\u001b[39;00m:\n\u001b[1;32m---> 20\u001b[0m     \u001b[39mimport\u001b[39;00m \u001b[39m_pywrap_tensorflow\u001b[39;00m\n\u001b[0;32m     21\u001b[0m     \u001b[39mreturn\u001b[39;00m _pywrap_tensorflow\n",
      "\u001b[1;31mModuleNotFoundError\u001b[0m: No module named '_pywrap_tensorflow'",
      "\nDuring handling of the above exception, another exception occurred:\n",
      "\u001b[1;31mImportError\u001b[0m                               Traceback (most recent call last)",
      "Cell \u001b[1;32mIn[6], line 1\u001b[0m\n\u001b[1;32m----> 1\u001b[0m \u001b[39mimport\u001b[39;00m \u001b[39mtensorflow\u001b[39;00m \u001b[39mas\u001b[39;00m \u001b[39mtf\u001b[39;00m\n\u001b[0;32m      2\u001b[0m \u001b[39mfrom\u001b[39;00m \u001b[39mtensorflow\u001b[39;00m \u001b[39mimport\u001b[39;00m keras\n\u001b[0;32m      4\u001b[0m \u001b[39m# Load the MNIST dataset\u001b[39;00m\n",
      "File \u001b[1;32mc:\\Users\\kumar\\AppData\\Local\\Programs\\Python\\Python311\\Lib\\site-packages\\tensorflow\\__init__.py:24\u001b[0m\n\u001b[0;32m     21\u001b[0m \u001b[39mfrom\u001b[39;00m \u001b[39m__future__\u001b[39;00m \u001b[39mimport\u001b[39;00m print_function\n\u001b[0;32m     23\u001b[0m \u001b[39m# pylint: disable=wildcard-import\u001b[39;00m\n\u001b[1;32m---> 24\u001b[0m \u001b[39mfrom\u001b[39;00m \u001b[39mtensorflow\u001b[39;00m\u001b[39m.\u001b[39;00m\u001b[39mpython\u001b[39;00m \u001b[39mimport\u001b[39;00m \u001b[39m*\u001b[39m\n\u001b[0;32m     25\u001b[0m \u001b[39m# pylint: enable=wildcard-import\u001b[39;00m\n\u001b[0;32m     26\u001b[0m \n\u001b[0;32m     27\u001b[0m \u001b[39m# Lazily import the `tf.contrib` module. This avoids loading all of the\u001b[39;00m\n\u001b[0;32m     28\u001b[0m \u001b[39m# dependencies of `tf.contrib` at `import tensorflow` time.\u001b[39;00m\n\u001b[0;32m     29\u001b[0m \u001b[39mclass\u001b[39;00m \u001b[39m_LazyContribLoader\u001b[39;00m(\u001b[39mobject\u001b[39m):\n",
      "File \u001b[1;32mc:\\Users\\kumar\\AppData\\Local\\Programs\\Python\\Python311\\Lib\\site-packages\\tensorflow\\python\\__init__.py:72\u001b[0m\n\u001b[0;32m     67\u001b[0m \u001b[39mexcept\u001b[39;00m \u001b[39mImportError\u001b[39;00m:\n\u001b[0;32m     68\u001b[0m   msg \u001b[39m=\u001b[39m \u001b[39m\"\"\"\u001b[39m\u001b[39m%s\u001b[39;00m\u001b[39m\\n\u001b[39;00m\u001b[39m\\n\u001b[39;00m\u001b[39mFailed to load the native TensorFlow runtime.\u001b[39m\u001b[39m\\n\u001b[39;00m\n\u001b[0;32m     69\u001b[0m \u001b[39mSee https://github.com/tensorflow/tensorflow/blob/master/tensorflow/g3doc/get_started/os_setup.md#import_error\u001b[39m\u001b[39m\\n\u001b[39;00m\n\u001b[0;32m     70\u001b[0m \u001b[39mfor some common reasons and solutions.  Include the entire stack trace\u001b[39m\n\u001b[0;32m     71\u001b[0m \u001b[39mabove this error message when asking for help.\u001b[39m\u001b[39m\"\"\"\u001b[39m \u001b[39m%\u001b[39m traceback\u001b[39m.\u001b[39mformat_exc()\n\u001b[1;32m---> 72\u001b[0m   \u001b[39mraise\u001b[39;00m \u001b[39mImportError\u001b[39;00m(msg)\n\u001b[0;32m     74\u001b[0m \u001b[39m# Protocol buffers\u001b[39;00m\n\u001b[0;32m     75\u001b[0m \u001b[39mfrom\u001b[39;00m \u001b[39mtensorflow\u001b[39;00m\u001b[39m.\u001b[39;00m\u001b[39mcore\u001b[39;00m\u001b[39m.\u001b[39;00m\u001b[39mframework\u001b[39;00m\u001b[39m.\u001b[39;00m\u001b[39mgraph_pb2\u001b[39;00m \u001b[39mimport\u001b[39;00m \u001b[39m*\u001b[39m\n",
      "\u001b[1;31mImportError\u001b[0m: Traceback (most recent call last):\n  File \"c:\\Users\\kumar\\AppData\\Local\\Programs\\Python\\Python311\\Lib\\site-packages\\tensorflow\\python\\pywrap_tensorflow.py\", line 18, in swig_import_helper\n    fp, pathname, description = imp.find_module('_pywrap_tensorflow', [dirname(__file__)])\n                                ^^^^^^^^^^^^^^^^^^^^^^^^^^^^^^^^^^^^^^^^^^^^^^^^^^^^^^^^^^\n  File \"c:\\Users\\kumar\\AppData\\Local\\Programs\\Python\\Python311\\Lib\\imp.py\", line 297, in find_module\n    raise ImportError(_ERR_MSG.format(name), name=name)\nImportError: No module named '_pywrap_tensorflow'\n\nDuring handling of the above exception, another exception occurred:\n\nTraceback (most recent call last):\n  File \"c:\\Users\\kumar\\AppData\\Local\\Programs\\Python\\Python311\\Lib\\site-packages\\tensorflow\\python\\__init__.py\", line 66, in <module>\n    from tensorflow.python import pywrap_tensorflow\n  File \"c:\\Users\\kumar\\AppData\\Local\\Programs\\Python\\Python311\\Lib\\site-packages\\tensorflow\\python\\pywrap_tensorflow.py\", line 28, in <module>\n    _pywrap_tensorflow = swig_import_helper()\n                         ^^^^^^^^^^^^^^^^^^^^\n  File \"c:\\Users\\kumar\\AppData\\Local\\Programs\\Python\\Python311\\Lib\\site-packages\\tensorflow\\python\\pywrap_tensorflow.py\", line 20, in swig_import_helper\n    import _pywrap_tensorflow\nModuleNotFoundError: No module named '_pywrap_tensorflow'\n\n\nFailed to load the native TensorFlow runtime.\n\nSee https://github.com/tensorflow/tensorflow/blob/master/tensorflow/g3doc/get_started/os_setup.md#import_error\n\nfor some common reasons and solutions.  Include the entire stack trace\nabove this error message when asking for help."
     ]
    }
   ],
   "source": [
    "import tensorflow as tf\n",
    "from tensorflow import keras\n",
    "\n",
    "# Load the MNIST dataset\n",
    "mnist = keras.datasets.mnist\n",
    "(train_images, train_labels), (test_images, test_labels) = mnist.load_data()\n",
    "\n",
    "# Preprocess the data\n",
    "train_images = train_images / 255.0\n",
    "test_images = test_images / 255.0\n",
    "\n",
    "# Define the model architecture\n",
    "model = keras.Sequential([\n",
    "    keras.layers.Flatten(input_shape=(28, 28)),\n",
    "    keras.layers.Dense(128, activation='relu'),\n",
    "    keras.layers.Dense(10, activation='softmax')\n",
    "])\n",
    "\n",
    "# Compile the model\n",
    "model.compile(optimizer='adam',\n",
    "              loss='sparse_categorical_crossentropy',\n",
    "              metrics=['accuracy'])\n",
    "\n",
    "# Train the model\n",
    "model.fit(train_images, train_labels, epochs=10)\n",
    "\n",
    "# Evaluate the model\n",
    "test_loss, test_acc = model.evaluate(test_images, test_labels)\n",
    "print('Test accuracy:', test_acc)\n"
   ]
  },
  {
   "cell_type": "markdown",
   "metadata": {},
   "source": [
    "### Basic Tenserflow Model"
   ]
  },
  {
   "cell_type": "code",
   "execution_count": 3,
   "metadata": {},
   "outputs": [
    {
     "name": "stdout",
     "output_type": "stream",
     "text": [
      "Requirement already satisfied: keras in c:\\users\\kumar\\appdata\\local\\programs\\python\\python311\\lib\\site-packages (2.12.0)\n",
      "Note: you may need to restart the kernel to use updated packages.\n"
     ]
    }
   ],
   "source": [
    "%pip install keras"
   ]
  },
  {
   "cell_type": "code",
   "execution_count": 2,
   "metadata": {},
   "outputs": [
    {
     "ename": "SyntaxError",
     "evalue": "incomplete input (3832545544.py, line 20)",
     "output_type": "error",
     "traceback": [
      "\u001b[1;36m  Cell \u001b[1;32mIn[2], line 20\u001b[1;36m\u001b[0m\n\u001b[1;33m    \u001b[0m\n\u001b[1;37m    ^\u001b[0m\n\u001b[1;31mSyntaxError\u001b[0m\u001b[1;31m:\u001b[0m incomplete input\n"
     ]
    }
   ],
   "source": [
    "import tensorflow as tf\n",
    "\n",
    "# Load the MNIST dataset\n",
    "(x_train, y_train), (x_test, y_test) = tf.keras.datasets.mnist.load_data()\n",
    "\n",
    "# Normalize pixel values to between 0 and 1\n",
    "x_train = x_train / 255.0\n",
    "x_test = x_test / 255.0\n",
    "\n",
    "# Define the model architecture\n",
    "model = tf.keras.models.Sequential([\n",
    "    tf.keras.layers.Flatten(input_shape=(28, 28)),\n",
    "    tf.keras.layers.Dense(128, activation='relu'),\n",
    "    tf.keras.layers.Dense(10, activation='softmax')\n",
    "])\n",
    "\n",
    "# Compile the model\n",
    "model.compile(optimizer='adam',\n",
    "              loss='sparse_categorical_crossentropy',\n",
    "             \n"
   ]
  }
 ],
 "metadata": {
  "kernelspec": {
   "display_name": "Python 3 (ipykernel)",
   "language": "python",
   "name": "python3"
  },
  "language_info": {
   "codemirror_mode": {
    "name": "ipython",
    "version": 3
   },
   "file_extension": ".py",
   "mimetype": "text/x-python",
   "name": "python",
   "nbconvert_exporter": "python",
   "pygments_lexer": "ipython3",
   "version": "3.11.3"
  }
 },
 "nbformat": 4,
 "nbformat_minor": 2
}
